2024-02-20 08:40:00,672 Minimum price: 10, Maximum price: 350
Traceback (most recent call last):
  File "/home/chaz/miniconda3/envs/mlflow-d6c04384fb9356865b6d231fc3cbd1b1b9b4863e/lib/python3.9/site-packages/pandas/core/indexes/base.py", line 2895, in get_loc
    return self._engine.get_loc(casted_key)
  File "pandas/_libs/index.pyx", line 70, in pandas._libs.index.IndexEngine.get_loc
  File "pandas/_libs/index.pyx", line 101, in pandas._libs.index.IndexEngine.get_loc
  File "pandas/_libs/hashtable_class_helper.pxi", line 1675, in pandas._libs.hashtable.PyObjectHashTable.get_item
  File "pandas/_libs/hashtable_class_helper.pxi", line 1683, in pandas._libs.hashtable.PyObjectHashTable.get_item
KeyError: 'none'
The above exception was the direct cause of the following exception:
Traceback (most recent call last):
  File "/home/chaz/Project-Build-an-ML-Pipeline-Starter/src/train_random_forest/run.py", line 293, in <module>
    go(args)
  File "/home/chaz/Project-Build-an-ML-Pipeline-Starter/src/train_random_forest/run.py", line 65, in go
    X, y, test_size=args.val_size, stratify=X[args.stratify_by], random_state=args.random_seed
  File "/home/chaz/miniconda3/envs/mlflow-d6c04384fb9356865b6d231fc3cbd1b1b9b4863e/lib/python3.9/site-packages/pandas/core/frame.py", line 2906, in __getitem__
    indexer = self.columns.get_loc(key)
  File "/home/chaz/miniconda3/envs/mlflow-d6c04384fb9356865b6d231fc3cbd1b1b9b4863e/lib/python3.9/site-packages/pandas/core/indexes/base.py", line 2897, in get_loc
    raise KeyError(key) from err
KeyError: 'none'